<?xml version="1.0"?>

<robot xmlns:xacro="http://www.ros.org/wiki/xacro" name="traktor">

    <xacro:include filename="sensors/sonar.xacro"/>
    <xacro:include filename="sensors/lidar.xacro"/>
    <!-- <xacro:include filename="sensors/imu.xacro"/> -->
    <!-- <xacro:include filename="sensors/cam.xacro"/> -->

    
<link name="base_link">
  <inertial>
    <origin xyz="0.0 0.0 0.0" rpy="0.0 0.0 0.0"/>
    <mass value="10"/>
    <inertia ixx="24.166666666666668" ixy="0" ixz="0" iyy="28.333333333333336" iyz="0" izz="10.833333333333334"/>
  </inertial>
  <visual name="chassis">
    <origin xyz="0.0 0.0 0.0" rpy="0.0 0.0 0.0"/> 
    <!--  <mesh filename="package://your_package/meshes/your_mesh.stl"/> -->
    <geometry>
      <box size="2.5 1.2 1"/>
    </geometry>
    <material name="">
      <color rgba="1.0 0.0 0.0 1.0"/>
      <texture filename=""/>
    </material>
  </visual>
  <collision>
    <origin xyz="0.0 0.0 0.0" rpy="0.0 0.0 0.0"/> 
    <!--  <mesh filename="package://your_package/meshes/your_mesh.stl"/> -->
    <geometry>
      <box size="2.5 1.2 1"/>
    </geometry>
  </collision>
</link>



<!-- Right wheel steer  -->

<link name="right_wheel_steer">
  <visual>
    <geometry>
      <cylinder length="0.05" radius="0.02"/>
    </geometry>
    <material name="black"/>
  </visual>
  <collision>
    <geometry>
      <cylinder length="0.05" radius="0.02"/>
    </geometry>
  </collision>
  <inertial>
    <origin xyz="0.0 0.0 0.0" rpy="0.0 0.0 0.0"/>
    <mass value="1"/>
    <inertia ixx="0.07583333333333334" ixy="0" ixz="0" iyy="0.07583333333333334" iyz="0" izz="0.125"/>
  </inertial>
</link>

<joint name="right_wheel_steer_joint" type="revolute"> 
  <parent link="base_link"/>
  <child link="right_wheel_steer"/>
  <origin xyz="0.75 -0.85 -0.5" rpy="1.5707 0 0"/>
  <axis xyz="0 1 0"/>
  <limit effort="100" velocity="1" lower="-1" upper="1"/>
  <dynamics damping="0.0" friction="0.0"/>
</joint>


<!-- Front right wheel -->

<link name="front_right_wheel"> 
  <inertial>
    <origin xyz="0.0 0.0 0.0" rpy="0.0 0.0 0.0"/>
    <mass value="1"/>
    <inertia ixx="0.07583333333333334" ixy="0" ixz="0" iyy="0.07583333333333334" iyz="0" izz="0.125"/>
  </inertial>
  <visual name="">
    <origin xyz="0.0 0.0 0.0" rpy="0.0 0.0 0.0"/> 
    <!--  <mesh filename="package://your_package/meshes/your_mesh.stl"/> -->
    <geometry>
      <cylinder length="0.20" radius="0.25"/>
    </geometry>
    <material name="">
      <color rgba="0.0 0.0 0.0 1.0"/>
      <texture filename=""/>
    </material>
  </visual>
  <collision>
    <origin xyz="0.0 0.0 0.0" rpy="0.0 0.0 0.0"/> 
    <!--  <mesh filename="package://your_package/meshes/your_mesh.stl"/> -->
    <geometry>
      <cylinder length="0.20" radius="0.25"/>
    </geometry>
  </collision>
</link>


<joint name="front_right_wheel_joint" type="continuous"> 
  <parent link="right_wheel_steer"/>
  <child link="front_right_wheel"/>
  <origin xyz="0.0 0.0 0.0" rpy="0 0 0"/>
  <axis xyz="0 0 -1"/>
  <limit effort="100" velocity="100"/>
  <dynamics damping="0.0" friction="0.0"/>
</joint>


<!-- Rear right wheel -->

<link name="rear_right_wheel"> 
  <inertial>
    <origin xyz="0.0 0.0 0.0" rpy="0.0 0.0 0.0"/>
    <mass value="1"/>
    <inertia ixx="0.07583333333333334" ixy="0" ixz="0" iyy="0.07583333333333334" iyz="0" izz="0.125"/>
  </inertial>
  <visual name="">
    <origin xyz="0.0 0.0 0.0" rpy="0.0 0.0 0.0"/> 
    <!--  <mesh filename="package://your_package/meshes/your_mesh.stl"/> -->
    <geometry>
      <cylinder length="0.20" radius="0.4"/>
    </geometry>
    <material name="">
      <color rgba="0.0 0.0 0.0 1.0"/>
      <texture filename=""/>
    </material>
  </visual>
  <collision>
    <origin xyz="0.0 0.0 0.0" rpy="0.0 0.0 0.0"/> 
    <!--  <mesh filename="package://your_package/meshes/your_mesh.stl"/> -->
    <geometry>
      <cylinder length="0.20" radius="0.4"/>
    </geometry>
  </collision>
</link>


<joint name="rear_right_wheel_joint" type="continuous"> 
  <parent link="base_link"/>
  <child link="rear_right_wheel"/>
    <origin xyz="-1.25 -0.85 -0.35" rpy="1.5707 0 0"/>
  <axis xyz="0 0 -1"/>
  <limit effort="100" velocity="100"/>
  <dynamics damping="0.0" friction="0.0"/>
</joint>


<!-- Left_wheel_steer -->

<link name="left_wheel_steer"> 
  <inertial>
    <origin xyz="0.0 0.0 0.0" rpy="0.0 0.0 0.0"/>
    <mass value="1"/>
    <inertia ixx="0.07583333333333334" ixy="0" ixz="0" iyy="0.07583333333333334" iyz="0" izz="0.125"/>
  </inertial>
  <visual>
    <geometry>
      <cylinder length="0.05" radius="0.02"/>
    </geometry>
    <collision>
      <geometry>
        <cylinder length="0.05" radius="0.02"/>
      </geometry>
    </collision>
    <material name="black"/>
  </visual>
</link>

<joint name="left_wheel_steer_joint" type="revolute">
  <parent link="base_link"/>
  <child link="left_wheel_steer"/>
  <origin xyz="0.75 0.85 -0.5" rpy="1.5707 0 0"/>
  <axis xyz="0 1 0"/>
  <limit effort="100" velocity="1" lower="-1" upper="1"/>
  <dynamics damping="0.0" friction="0.0"/>
</joint>


<!-- Front left wheel -->

<link name="front_left_wheel"> 
  <inertial>
    <origin xyz="0.0 0.0 0.0" rpy="0.0 0.0 0.0"/>
    <mass value="1"/>
    <inertia ixx="0.07583333333333334" ixy="0" ixz="0" iyy="0.07583333333333334" iyz="0" izz="0.125"/>
  </inertial>
  <visual name="">
    <origin xyz="0.0 0.0 0.0" rpy="0.0 0.0 0.0"/> 
    <!--  <mesh filename="package://your_package/meshes/your_mesh.stl"/> -->
    <geometry>
      <cylinder length="0.20" radius="0.25"/>
    </geometry>
    <material name="">
      <color rgba="0.0 0.0 0.0 1.0"/>
      <texture filename=""/>
    </material>
  </visual>
  <collision>
    <origin xyz="0.0 0.0 0.0" rpy="0.0 0.0 0.0"/> 
    <!--  <mesh filename="package://your_package/meshes/your_mesh.stl"/> -->
    <geometry>
      <cylinder length="0.20" radius="0.25"/>
    </geometry>
  </collision>
</link>


<joint name="front_left_wheel_joint" type="continuous"> 
  <parent link="left_wheel_steer"/>
  <child link="front_left_wheel"/>
  <origin xyz="0.0 0.0 0.0" rpy="0 0 0"/>
  <axis xyz="0 0 -1"/>
  <limit effort="100" velocity="100"/>
  <dynamics damping="0.0" friction="0.0"/>
</joint>


<!-- Rear left wheel -->

<link name="rear_left_wheel"> 
  <inertial>
    <origin xyz="0.0 0.0 0.0" rpy="0.0 0.0 0.0"/>
    <mass value="1"/>
    <inertia ixx="0.07583333333333334" ixy="0" ixz="0" iyy="0.07583333333333334" iyz="0" izz="0.125"/>
  </inertial>
  <visual name="">
    <origin xyz="0.0 0.0 0.0" rpy="0.0 0.0 0.0"/>
    <geometry>
      <cylinder length="0.20" radius="0.4"/>
    </geometry>
    <material name="">
      <color rgba="0.0 0.0 0.0 1.0"/>
      <texture filename=""/>
    </material>
  </visual>
  <collision>
    <origin xyz="0.0 0.0 0.0" rpy="0.0 0.0 0.0"/>
    <geometry>
      <cylinder length="0.20" radius="0.4"/> 
    </geometry>
  </collision>
</link>



<joint name="rear_left_wheel_joint" type="continuous"> <!-- SOL ARKA TEKER DİFERANSİYEL VE SOL ARKA TEKER JOİNTİ-->
  <parent link="base_link"/>
  <child link="rear_left_wheel"/>
    <origin xyz="-1.25 0.85 -0.35" rpy="1.5707 0 0"/>
  <axis xyz="0 0 -1"/>
  <limit effort="100" velocity="100"/>
  <dynamics damping="0.0" friction="0.0"/>
</joint>



<!-- GPS LINK -->
<link name="gps_link">
  <inertial>
    <origin xyz="0.0 0.0 0.0" rpy="0.0 0.0 0.0"/>
    <mass value="0.1"/>
    <inertia ixx="0.001" ixy="0" ixz="0" iyy="0.001" iyz="0" izz="0.001"/>
  </inertial>
  <visual name="">
    <origin xyz="0.0 0.0 0.0" rpy="0.0 0.0 0.0"/>
    <geometry>
      <box size="0.1 0.1 0.1"/>
    </geometry>
    <material name="">
      <color rgba="0.0 0.0 0.0 1.0"/>
      <texture filename=""/>
    </material>
  </visual>
  <collision>
    <origin xyz="0.0 0.0 0.0" rpy="0.0 0.0 0.0"/>
    <geometry>
      <box size="0.1 0.1 0.1"/>
    </geometry>
  </collision>
</link>

<!-- GPS JOINT -->
<joint name="gps_joint" type="fixed">
  <parent link="base_link"/>
  <child link="gps_link"/>
  <origin xyz="0.0 0.0 0" rpy="0.0 0.0 0.0"/>
</joint>

<!-- GPS PLUGIN -->
  <gazebo reference="gps_link">
    <sensor name="gps_sensor" type="gps">
      <always_on>true</always_on>
      <update_rate>1.0</update_rate>
      <plugin name="gps_controller" filename="libgazebo_ros_gps_sensor.so">
        <ros>
          <!-- <namespace>/br</namespace> -->
          <remapping>gps_controller/out:=/gps/fix</remapping>
        </ros>
        <frame_name>gps_link</frame_name>
        <offset>0 0 0</offset>
        <drift>0.001 0.001 0.001</drift>
        <gaussianNoise>0.05 0.05 0.05</gaussianNoise>
        <velocityDrift>0.001 0.001 0.001</velocityDrift>
        <velocityGaussianNoise>0.5 0.5 0.5</velocityGaussianNoise>
      </plugin>
    </sensor>
    <material>Gazebo/Turquoise</material>
  </gazebo>


<!-- İMU SENSÖR LİNK,JOİNT -->
<link name="imu_link">
  <inertial>
    <origin xyz="0.0 0.0 0.0" rpy="0.0 0.0 0.0"/>
    <mass value="0.01"/>
    <inertia ixx="0.0001" ixy="0.0" ixz="0.0" iyy="0.0001" iyz="0.0" izz="0.0001"/>
  </inertial>
  <visual name="">
    <origin xyz="0.0 0.0 0.0" rpy="0.0 0.0 0.0"/>
    <geometry>
      <box size="0.1 0.1 0.02"/>
    </geometry>
    <material name="">
      <color rgba="1.0 0.0 0.0 1.0"/>
      <texture filename=""/>
    </material>
  </visual>
  <collision>
    <origin xyz="0.0 0.0 0.0" rpy="0.0 0.0 0.0"/>
    <geometry>
      <box size="0.1 0.1 0.02"/>
    </geometry>
  </collision>
</link>

<joint name="imu_joint" type="fixed">
  <parent link="base_link"/>
  <child link="imu_link"/>
  <origin xyz="1.0 0.0 0" rpy="0.0 0.0 0.0"/>
</joint>

<!-- İMU SENSÖR PLUGİN -->
  <gazebo reference="imu_link">
    <sensor name="imu_sensor" type="imu">
      <plugin filename="libgazebo_ros_imu_sensor.so" name="imu_plugin">
        <ros>
          <remapping>~/out:=/imu</remapping>
        </ros>
        <initial_orientation_as_reference>false</initial_orientation_as_reference>
      </plugin>
      <always_on>true</always_on>
      <update_rate>100</update_rate>
      <visualize>true</visualize>
      <imu>
        <angular_velocity>
          <x>
            <noise type="gaussian">
              <mean>0.0</mean>
              <stddev>2e-4</stddev>
              <bias_mean>0.0000075</bias_mean>
              <bias_stddev>0.0000008</bias_stddev>
            </noise>
          </x>
          <y>
            <noise type="gaussian">
              <mean>0.0</mean>
              <stddev>2e-4</stddev>
              <bias_mean>0.0000075</bias_mean>
              <bias_stddev>0.0000008</bias_stddev>
            </noise>
          </y>
          <z>
            <noise type="gaussian">
              <mean>0.0</mean>
              <stddev>2e-4</stddev>
              <bias_mean>0.0000075</bias_mean>
              <bias_stddev>0.0000008</bias_stddev>
            </noise>
          </z>
        </angular_velocity>
        <linear_acceleration>
          <x>
            <noise type="gaussian">
              <mean>0.0</mean>
              <stddev>1.7e-2</stddev>
              <bias_mean>0.1</bias_mean>
              <bias_stddev>0.001</bias_stddev>
            </noise>
          </x>
          <y>
            <noise type="gaussian">
              <mean>0.0</mean>
              <stddev>1.7e-2</stddev>
              <bias_mean>0.1</bias_mean>
              <bias_stddev>0.001</bias_stddev>
            </noise>
          </y>
          <z>
            <noise type="gaussian">
              <mean>0.0</mean>
              <stddev>1.7e-2</stddev>
              <bias_mean>0.1</bias_mean>
              <bias_stddev>0.001</bias_stddev>
            </noise>
          </z>
        </linear_acceleration>
      </imu>
    </sensor>
    <material>Gazebo/Turquoise</material>
  </gazebo>



<!-- LİDAR LİNK -->
  <link name="lidar_link">
    <collision>
      <origin xyz="0 0 0" rpy="0 0 0"/>
      <geometry>
        <cylinder radius="0.1" length="0.1"/>
      </geometry>
    </collision>

    <visual>
      <origin xyz="0 0 0" rpy="0 0 0"/>
      <geometry>
        <cylinder radius="0.1" length="0.1"/>
      </geometry>
    </visual>

    <inertial>
      <mass value="1e-5" />
      <origin xyz="0 0 0" rpy="0 0 0"/>
      <inertia ixx="1e-6" ixy="0" ixz="0" iyy="1e-6" iyz="0" izz="1e-6" />
    </inertial>
  </link>


  <joint name="lidar_joint" type="fixed">
    <axis xyz="0 1 0" />
    <origin xyz="1 0 0.51" rpy="0 0 0"/>
    <parent link="base_link"/>
    <child link="lidar_link"/>
  </joint> 

<!-- LİDAR PLUGİN -->
<gazebo reference="lidar_link">
    <sensor name="lidar" type="ray">
      <pose>0.215 0 0.215 0 0 0</pose>
      <always_on>true</always_on>
      <visualize>true</visualize>
      <update_rate>10</update_rate>
      <ray>
        <scan>
          <horizontal>
            <samples>360</samples>
            <resolution>1.00000</resolution>
            <min_angle>-3.14</min_angle>
            <max_angle>3.14</max_angle>
          </horizontal>
        </scan>
        <range>
          <min>0.120000</min>
          <max>15</max>
          <resolution>0.015000</resolution>
        </range>
        <noise>
          <type>gaussian</type>
          <mean>0.0</mean>
          <stddev>0.01</stddev>
        </noise>
      </ray>
      <plugin name="scan" filename="libgazebo_ros_ray_sensor.so">
        <ros>
          <remapping>~/out:=scan</remapping>
        </ros>
        <output_type>sensor_msgs/LaserScan</output_type>
        <frame_name>lidar_link</frame_name>
      </plugin>
    </sensor>
    <material>Gazebo/Red</material>
  </gazebo>

  <!-- Camera link -->

    <joint name="cam_joint" type="fixed">
        <parent link="base_link"/>
        <child link="cam_link"/>
        <origin xyz="1.25 0 0.41" rpy="0 0 0"/>
    </joint>
 
    <link name="cam_link">
        <visual>
            <geometry>
                <box size="0.030 0.05 0.05"/>
            </geometry>
            <material name="black"/>
        </visual>
    </link>
 
 
    <joint name="cam_optical_joint" type="fixed">
        <parent link="cam_link"/>
        <child link="cam_link_optical"/>
        <origin xyz="0 0 0" rpy="${-pi/2} 0 ${-pi/2}"/>
    </joint>
 
    <link name="cam_link_optical"> </link>
 

    <gazebo reference="cam_link">
        <material>Gazebo/Turquoise</material>
        <sensor name="camera" type="camera">
            <pose> 0 0 0 0 0 0 </pose>
            <visualize>true</visualize>
            <update_rate>10</update_rate>
            <camera>
                <horizontal_fov>1.089</horizontal_fov>
                <image>
                    <format>R8G8B8</format>
                    <width>640</width>
                    <height>480</height>
                </image>
                <clip>
                    <near>0.05</near>
                    <far>8.0</far>
                </clip>
            </camera>
            <plugin name="camera_controller" filename="libgazebo_ros_camera.so">
                <frame_name>cam_link_optical</frame_name>
            </plugin>
        </sensor>
    </gazebo> 



  <!--Depth camera link -->

    <joint name="depth_cam_joint" type="fixed">
        <parent link="base_link"/>
        <child link="depth_cam_link"/>
        <origin xyz="1.25 0 0.48" rpy="0 0 0"/>
    </joint>
 
    <link name="depth_cam_link">
        <visual>
            <geometry>
                <box size="0.030 0.1 0.05"/>
            </geometry>
            <material name="black"/>
        </visual>
    </link>
 
 
    <joint name="depth_cam_optical_joint" type="fixed">
        <parent link="depth_cam_link"/>
        <child link="depth_cam_link_optical"/>
        <origin xyz="0 0 0" rpy="${-pi/2} 0 ${-pi/2}"/>
    </joint>
 
    <link name="depth_cam_link_optical"> </link>
 

    <gazebo reference="depth_cam_link">
        <material>Gazebo/Turquoise</material>
        <sensor name="depth_camera" type="depth">
            <pose> 0 0 0 0 0 0 </pose>
            <visualize>true</visualize>
            <update_rate>10</update_rate>
            <camera>
                <horizontal_fov>1.089</horizontal_fov>
                <image>
                    <format>B8R8G8</format>
                    <width>640</width>
                    <height>480</height>
                </image>
                <clip>
                    <near>0.05</near>
                    <far>8.0</far>
                </clip>
            </camera>
            <plugin name="depth_camera_controller" filename="libgazebo_ros_camera.so">
                <frame_name>depth_cam_link_optical</frame_name>
                <min_depth>0.1</min_depth>
                <max_depth>100</max_depth>
            </plugin>
        </sensor>
    </gazebo> 



<!-- ACKERMANN DRİVE PLUGİN  -->
<gazebo>
  <plugin name="gazebo_ros_ackermann_drive" filename="libgazebo_ros_ackermann_drive.so">

    <ros>
      <!-- <namespace>demo</namespace> -->
      <remapping>cmd_vel:=cmd_vel</remapping>
      <remapping>odom:=odom</remapping>
      <remapping>distance:=distance_demo</remapping>
    </ros>

    <update_rate>100.0</update_rate>

    <!-- wheels -->
    <front_left_joint>front_left_wheel_joint</front_left_joint>
    <front_right_joint>front_right_wheel_joint</front_right_joint>
    <rear_left_joint>rear_left_wheel_joint</rear_left_joint>
    <rear_right_joint>rear_right_wheel_joint</rear_right_joint>
    <left_steering_joint>left_wheel_steer_joint</left_steering_joint>
    <right_steering_joint>right_wheel_steer_joint</right_steering_joint>


    <!-- Max absolute steer angle for tyre in radians-->
    <!-- Any cmd_vel angular z greater than this would be capped -->
    <max_steer>0.6458</max_steer>

    <!-- Max absolute steering angle of steering wheel -->
    <max_steering_angle>7.85</max_steering_angle>

    <!-- Max absolute linear speed in m/s -->
    <max_speed>20</max_speed>

    <!-- PID tuning -->
    <left_steering_pid_gain>1500 0 1</left_steering_pid_gain>
    <left_steering_i_range>0 0</left_steering_i_range>
    <right_steering_pid_gain>1500 0 1</right_steering_pid_gain>
    <right_steering_i_range>0 0</right_steering_i_range>
    <linear_velocity_pid_gain>1000 0 1</linear_velocity_pid_gain>
    <linear_velocity_i_range>0 0</linear_velocity_i_range>

    <!-- output -->
    <publish_odom>true</publish_odom>
    <publish_odom_tf>true</publish_odom_tf>
    <publish_wheel_tf>true</publish_wheel_tf>
    <publish_distance>true</publish_distance>

    <odometry_frame>odom</odometry_frame>
    <robot_base_frame>base_link</robot_base_frame>

  </plugin>
</gazebo>


<!-- LİNK COLORS  -->

<gazebo reference="base_link">
  <material>Gazebo/Red</material>
</gazebo>
<gazebo reference="right_wheel_steer">
  <material>Gazebo/Green</material>
</gazebo>
<gazebo reference="left_wheel_steer">
  <material>Gazebo/Green</material>
</gazebo>
<gazebo reference="front_right_wheel">
  <material>Gazebo/Black</material>
</gazebo>
<gazebo reference="front_left_wheel">
  <material>Gazebo/Black</material>
</gazebo>
<gazebo reference="rear_left_wheel">
  <material>Gazebo/Black</material>
</gazebo>
<gazebo reference="rear_right_wheel">
  <material>Gazebo/Black</material>
</gazebo>

</robot>
